# 오류와 예외 처리
result = 0

try:
    [1,2,3][3]
    "a"+1
    4/0
except TypeError:
    result += 1
except ZeroDivisionError:
    result += 2
except IndexError:
    result += 3
finally:
    result += 4

print(result)

"""
=> 7이 출력된다.
1. result의 초깃값은 0이다.
2. try문 안의 [1,2,3][3]이라는 문장 수행 시 IndexError가 발생하여 except IndexError: 구문으로 이동하게 되어 result에 3이 더해져 3이 된다.
3. 최종적으로 finally 구문이 실행되어 result에 4가 더해져 7이 된다.
4. print(result)가 수행되어 result의 최종 값인 7이 출력된다.
"""



